Workbook
Name Slicer_City: #N/A
Name Slicer_Customer_Name: #N/A
Name Slicer_Months: #N/A
Name Slicer_Product_Sub_Category: #N/A
Name Slicer_Region1: #N/A
Name Slicer_Ship_Mode: #N/A

Sheet Dashboard

Sheet Region vs Salse
A3: Row Labels | B3: Sum of Sales
A4: Central | B4: 448284.7
A5: East | B5: 592171.49
A6: South | B6: 357105.12
A7: West | B7: 526776.57
A8: Grand Total | B8: 1924337.9
A11: =GETPIVOTDATA("Sales",$A$3) -> 1924337.9

Sheet Ship Mode Vs Salse
A3: Row Labels | B3: Sum of Sales
A4: Delivery Truck | B4: 789235.46
A5: Express Air | B5: 145050.22
A6: Regular Air | B6: 990052.2
A7: Grand Total | B7: 1924337.9
A12: =GETPIVOTDATA("Sales",$A$3) -> 1924337.9

Sheet Product
A3: Row Labels | B3: Sum of Sales
A4: Appliances | B4: 82201.15
A5: Binders and Binder Accessories | B5: 185928.14
A6: Bookcases | B6: 107796.09
A7: Chairs & Chairmats | B7: 261072.73
A8: Computer Peripherals | B8: 96261.3
A9: Copiers and Fax | B9: 99069.48
A10: Envelopes | B10: 10479.77
A11: Labels | B11: 4914.82
A12: Office Furnishings | B12: 98070.91
A13: Office Machines | B13: 318169.68
A14: Paper | B14: 55813.92
A15: Pens & Art Supplies | B15: 26071.61
... A21: Grand Total | B21: 1924337.9
B23: =GETPIVOTDATA("Sales",$A$3) -> 1924337.9

Sheet Month
A3: Row Labels | B3: Sum of Sales
A4: January | B4: 274766.92
A5: February | B5: 326101.47
A6: March | B6: 271696.67
A7: April | B7: 389831.95
A8: May | B8: 306572.07
A9: June | B9: 355368.8
A10: Grand Total | B10: 1924337.9

Sheet Customer name 
A3: Row Labels | B3: Sum of Sales
A4: Aaron Day | B4: 710.16
A5: Aaron Dillon | B5: 18.34
A6: Aaron Riggs | B6: 3598.26
A7: Aaron Shaffer | B7: 894.64
A8: Adam G Sawyer | B8: 1638.5
A9: Adam Saunders Gray | B9: 48.3
A10: Albert Frost | B10: 485.01
A11: Albert Maxwell | B11: 396.19
A12: Albert Tyson | B12: 1338.6
A13: Alex Harrell | B13: 267.89
A14: Alex Nicholson | B14: 191.68
A15: Alex Watkins | B15: 205.76
... A1134: Grand Total | B1134: 1924337.9

Sheet Orders
A1: Row ID | B1: Order Priority | C1: Discount | D1: Unit Price | E1: Shipping Cost | F1: Customer ID | G1: Repeat Customers | H1: Customer Name | I1: Ship Mode | J1: Customer Segment | K1: Product Category | L1: Product Sub-Category | M1: Product Container | N1: Product Name | O1: Product Base Margin | P1: Profit Margin | Q1: Country | R1: Region | S1: State or Province | T1: City | U1: Postal Code | V1: Order Date | W1: Order Month | X1: Order Year | Y1: Ship Date | Z1: Profit | AA1: Quantity ordered new | AB1: Sales | AC1: Order ID | AD1: Return Status
A2: 20847 | B2: High | C2: 0.01 | D2: 2.84 | E2: 0.93 | F2: 3 | G2: =IF(COUNTIF(Table1[Customer ID],Table1[[#This Row],[Customer ID]])>1,"Repeat Customer","One-Time Customer") -> One-Time Customer | H2: Bonnie Potter | I2: Express Air | J2: Corporate | K2: Office Supplies | L2: Pens & Art Supplies | M2: Wrap Bag | N2: SANFORD Liquid Accent™ Tank-Style Highlighters | O2: 0.54 | P2: =Table1[[#This Row],[Profit]]/Table1[[#This Row],[Sales]] -> 0.35049962 | Q2: United States | R2: West | S2: Washington | T2: Anacortes | U2: 98221 | V2: 42011 | W2: =TEXT(Table1[[#This Row],[Order Date]],"mmmm") -> January | X2: =TEXT(Table1[[#This Row],[Order Date]],"yyyy") -> 2015 | Y2: 42012 | Z2: 4.56 | AA2: 4 | AB2: 13.01 | AC2: 88522 | AD2: =IF(COUNTIF(Returns!$A$2:$A$1635,Orders!AC2)>0,"Returned","Not Returned") -> Not Returned
A3: 20228 | B3: Not Specified | C3: 0.02 | D3: 500.98 | E3: 26 | F3: 5 | G3: =IF(COUNTIF(Table1[Customer ID],Table1[[#This Row],[Customer ID]])>1,"Repeat Customer","One-Time Customer") -> One-Time Customer | H3: Ronnie Proctor | I3: Delivery Truck | J3: Home Office | K3: Furniture | L3: Chairs & Chairmats | M3: Jumbo Drum | N3: Global Troy™ Executive Leather Low-Back Tilter | O3: 0.6 | P3: =Table1[[#This Row],[Profit]]/Table1[[#This Row],[Sales]] -> 0.69 | Q3: United States | R3: West | S3: California | T3: San Gabriel | U3: 91776 | V3: 42168 | W3: =TEXT(Table1[[#This Row],[Order Date]],"mmmm") -> June | X3: =TEXT(Table1[[#This Row],[Order Date]],"yyyy") -> 2015 | Y3: 42170 | Z3: 4390.3665 | AA3: 12 | AB3: 6362.85 | AC3: 90193 | AD3: =IF(COUNTIF(Returns!$A$2:$A$1635,Orders!AC3)>0,"Returned","Not Returned") -> Not Returned
A4: 21776 | B4: Critical | C4: 0.06 | D4: 9.48 | E4: 7.29 | F4: 11 | G4: =IF(COUNTIF(Table1[Customer ID],Table1[[#This Row],[Customer ID]])>1,"Repeat Customer","One-Time Customer") -> One-Time Customer | H4: Marcus Dunlap | I4: Regular Air | J4: Home Office | K4: Furniture | L4: Office Furnishings | M4: Small Pack | N4: DAX Two-Tone Rosewood/Black Document Frame, Desktop, 5 x 7 | O4: 0.45 | P4: =Table1[[#This Row],[Profit]]/Table1[[#This Row],[Sales]] -> -0.25484063 | Q4: United States | R4: East | S4: New Jersey | T4: Roselle | U4: 7203 | V4: 42050 | W4: =TEXT(Table1[[#This Row],[Order Date]],"mmmm") -> February | X4: =TEXT(Table1[[#This Row],[Order Date]],"yyyy") -> 2015 | Y4: 42052 | Z4: -53.8096 | AA4: 22 | AB4: 211.15 | AC4: 90192 | AD4: =IF(COUNTIF(Returns!$A$2:$A$1635,Orders!AC4)>0,"Returned","Not Returned") -> Not Returned
A5: 24844 | B5: Medium | C5: 0.09 | D5: 78.69 | E5: 19.99 | F5: 14 | G5: =IF(COUNTIF(Table1[Customer ID],Table1[[#This Row],[Customer ID]])>1,"Repeat Customer","One-Time Customer") -> Repeat Customer | H5: Gwendolyn F Tyson | I5: Regular Air | J5: Small Business | K5: Furniture | L5: Office Furnishings | M5: Small Box | N5: Howard Miller 12-3/4 Diameter Accuwave DS ™ Wall Clock | O5: 0.43 | P5: =Table1[[#This Row],[Profit]]/Table1[[#This Row],[Sales]] -> 0.69 | Q5: United States | R5: Central | S5: Minnesota | T5: Prior Lake | U5: 55372 | V5: 42136 | W5: =TEXT(Table1[[#This Row],[Order Date]],"mmmm") -> May | X5: =TEXT(Table1[[#This Row],[Order Date]],"yyyy") -> 2015 | Y5: 42138 | Z5: 803.4705 | AA5: 16 | AB5: 1164.45 | AC5: 86838 | AD5: =IF(COUNTIF(Returns!$A$2:$A$1635,Orders!AC5)>0,"Returned","Not Returned") -> Not Returned
A6: 24846 | B6: Medium | C6: 0.08 | D6: 3.28 | E6: 2.31 | F6: 14 | G6: =IF(COUNTIF(Table1[Customer ID],Table1[[#This Row],[Customer ID]])>1,"Repeat Customer","One-Time Customer") -> Repeat Customer | H6: Gwendolyn F Tyson | I6: Regular Air | J6: Small Business | K6: Office Supplies | L6: Pens & Art Supplies | M6: Wrap Bag | N6: Newell 321 | O6: 0.56 | P6: =Table1[[#This Row],[Profit]]/Table1[[#This Row],[Sales]] -> -1.0809717 | Q6: United States | R6: Central | S6: Minnesota | T6: Prior Lake | U6: 55372 | V6: 42136 | W6: =TEXT(Table1[[#This Row],[Order Date]],"mmmm") -> May | X6: =TEXT(Table1[[#This Row],[Order Date]],"yyyy") -> 2015 | Y6: 42137 | Z6: -24.03 | AA6: 7 | AB6: 22.23 | AC6: 86838 | AD6: =IF(COUNTIF(Returns!$A$2:$A$1635,Orders!AC6)>0,"Returned","Not Returned") -> Not Returned
A7: 24847 | B7: Medium | C7: 0.05 | D7: 3.28 | E7: 4.2 | F7: 14 | G7: =IF(COUNTIF(Table1[Customer ID],Table1[[#This Row],[Customer ID]])>1,"Repeat Customer","One-Time Customer") -> Repeat Customer | H7: Gwendolyn F Tyson | I7: Regular Air | J7: Small Business | K7: Office Supplies | L7: Pens & Art Supplies | M7: Wrap Bag | N7: Newell 351 | O7: 0.56 | P7: =Table1[[#This Row],[Profit]]/Table1[[#This Row],[Sales]] -> -2.6468906 | Q7: United States | R7: Central | S7: Minnesota | T7: Prior Lake | U7: 55372 | V7: 42136 | W7: =TEXT(Table1[[#This Row],[Order Date]],"mmmm") -> May | X7: =TEXT(Table1[[#This Row],[Order Date]],"yyyy") -> 2015 | Y7: 42137 | Z7: -37.03 | AA7: 4 | AB7: 13.99 | AC7: 86838 | AD7: =IF(COUNTIF(Returns!$A$2:$A$1635,Orders!AC7)>0,"Returned","Not Returned") -> Not Returned
A8: 24848 | B8: Medium | C8: 0.05 | D8: 3.58 | E8: 1.63 | F8: 14 | G8: =IF(COUNTIF(Table1[Customer ID],Table1[[#This Row],[Customer ID]])>1,"Repeat Customer","One-Time Customer") -> Repeat Customer | H8: Gwendolyn F Tyson | I8: Regular Air | J8: Small Business | K8: Office Supplies | L8: Rubber Bands | M8: Wrap Bag | N8: OIC Colored Binder Clips, Assorted Sizes | O8: 0.36 | P8: =Table1[[#This Row],[Profit]]/Table1[[#This Row],[Sales]] -> -0.049789621 | Q8: United States | R8: Central | S8: Minnesota | T8: Prior Lake | U8: 55372 | V8: 42136 | W8: =TEXT(Table1[[#This Row],[Order Date]],"mmmm") -> May | X8: =TEXT(Table1[[#This Row],[Order Date]],"yyyy") -> 2015 | Y8: 42137 | Z8: -0.71 | AA8: 4 | AB8: 14.26 | AC8: 86838 | AD8: =IF(COUNTIF(Returns!$A$2:$A$1635,Orders!AC8)>0,"Returned","Not Returned") -> Not Returned
A9: 18181 | B9: Critical | C9: 0 | D9: 4.42 | E9: 4.99 | F9: 15 | G9: =IF(COUNTIF(Table1[Customer ID],Table1[[#This Row],[Customer ID]])>1,"Repeat Customer","One-Time Customer") -> Repeat Customer | H9: Timothy Reese | I9: Regular Air | J9: Small Business | K9: Office Supplies | L9: Envelopes | M9: Small Box | N9: Grip Seal Envelopes | O9: 0.38 | P9: =Table1[[#This Row],[Profit]]/Table1[[#This Row],[Sales]] -> -1.7872722 | Q9: United States | R9: East | S9: New York | T9: Smithtown | U9: 11787 | V9: 42102 | W9: =TEXT(Table1[[#This Row],[Order Date]],"mmmm") -> April | X9: =TEXT(Table1[[#This Row],[Order Date]],"yyyy") -> 2015 | Y9: 42103 | Z9: -59.82 | AA9: 7 | AB9: 33.47 | AC9: 86837 | AD9: =IF(COUNTIF(Returns!$A$2:$A$1635,Orders!AC9)>0,"Returned","Not Returned") -> Not Returned
A10: 20925 | B10: Medium | C10: 0.01 | D10: 35.94 | E10: 6.66 | F10: 15 | G10: =IF(COUNTIF(Table1[Customer ID],Table1[[#This Row],[Customer ID]])>1,"Repeat Customer","One-Time Customer") -> Repeat Customer | H10: Timothy Reese | I10: Regular Air | J10: Small Business | K10: Office Supplies | L10: Envelopes | M10: Small Box | N10: Tyvek ® Top-Opening Peel & Seel ® Envelopes, Gray | O10: 0.4 | P10: =Table1[[#This Row],[Profit]]/Table1[[#This Row],[Sales]] -> 0.69 | Q10: United States | R10: East | S10: New York | T10: Smithtown | U10: 11787 | V10: 42152 | W10: =TEXT(Table1[[#This Row],[Order Date]],"mmmm") -> May | X10: =TEXT(Table1[[#This Row],[Order Date]],"yyyy") -> 2015 | Y10: 42152 | Z10: 261.8757 | AA10: 10 | AB10: 379.53 | AC10: 86839 | AD10: =IF(COUNTIF(Returns!$A$2:$A$1635,Orders!AC10)>0,"Returned","Not Returned") -> Not Returned
A11: 26267 | B11: High | C11: 0.04 | D11: 2.98 | E11: 1.58 | F11: 16 | G11: =IF(COUNTIF(Table1[Customer ID],Table1[[#This Row],[Customer ID]])>1,"Repeat Customer","One-Time Customer") -> Repeat Customer | H11: Sarah Ramsey | I11: Regular Air | J11: Small Business | K11: Office Supplies | L11: Rubber Bands | M11: Wrap Bag | N11: Staples Gold Paper Clips | O11: 0.39 | P11: =Table1[[#This Row],[Profit]]/Table1[[#This Row],[Sales]] -> 0.13989362 | Q11: United States | R11: East | S11: New York | T11: Syracuse | U11: 13210 | V11: 42047 | W11: =TEXT(Table1[[#This Row],[Order Date]],"mmmm") -> February | X11: =TEXT(Table1[[#This Row],[Order Date]],"yyyy") -> 2015 | Y11: 42050 | Z11: 2.63 | AA11: 6 | AB11: 18.8 | AC11: 86836 | AD11: =IF(COUNTIF(Returns!$A$2:$A$1635,Orders!AC11)>0,"Returned","Not Returned") -> Not Returned
A12: 26268 | B12: High | C12: 0.05 | D12: 115.99 | E12: 2.5 | F12: 16 | G12: =IF(COUNTIF(Table1[Customer ID],Table1[[#This Row],[Customer ID]])>1,"Repeat Customer","One-Time Customer") -> Repeat Customer | H12: Sarah Ramsey | I12: Regular Air | J12: Small Business | K12: Technology | L12: Telephones and Communication | M12: Small Box | N12: StarTAC 7797 | O12: 0.55 | P12: =Table1[[#This Row],[Profit]]/Table1[[#This Row],[Sales]] -> 0.69 | Q12: United States | R12: East | S12: New York | T12: Syracuse | U12: 13210 | V12: 42047 | W12: =TEXT(Table1[[#This Row],[Order Date]],"mmmm") -> February | X12: =TEXT(Table1[[#This Row],[Order Date]],"yyyy") -> 2015 | Y12: 42049 | Z12: 652.7331 | AA12: 10 | AB12: 945.99 | AC12: 86836 | AD12: =IF(COUNTIF(Returns!$A$2:$A$1635,Orders!AC12)>0,"Returned","Not Returned") -> Not Returned
A13: 23890 | B13: High | C13: 0.05 | D13: 26.48 | E13: 6.93 | F13: 18 | G13: =IF(COUNTIF(Table1[Customer ID],Table1[[#This Row],[Customer ID]])>1,"Repeat Customer","One-Time Customer") -> One-Time Customer | H13: Laurie Hanna | I13: Regular Air | J13: Small Business | K13: Furniture | L13: Office Furnishings | M13: Small Box | N13: DAX Natural Wood-Tone Poster Frame | O13: 0.49 | P13: =Table1[[#This Row],[Profit]]/Table1[[#This Row],[Sales]] -> 0.69 | Q13: United States | R13: West | S13: Montana | T13: Helena | U13: 59601 | V13: 42139 | W13: =TEXT(Table1[[#This Row],[Order Date]],"mmmm") -> May | X13: =TEXT(Table1[[#This Row],[Order Date]],"yyyy") -> 2015 | Y13: 42140 | Z13: 314.4813 | AA13: 17 | AB13: 455.77 | AC13: 90031 | AD13: =IF(COUNTIF(Returns!$A$2:$A$1635,Orders!AC13)>0,"Returned","Not Returned") -> Not Returned
... A182: 19158 | B182: Medium | C182: 0.01 | D182: 29.1 | E182: 4 | F182: 331 | G182: =IF(COUNTIF(Table1[Customer ID],Table1[[#This Row],[Customer ID]])>1,"Repeat Customer","One-Time Customer") -> One-Time Customer | H182: Bradley Pollock | I182: Express Air | J182: Home Office | K182: Technology | L182: Computer Peripherals | M182: Small Box | N182: Acco Keyboard-In-A-Box® | O182: 0.78 | P182: =Table1[[#This Row],[Profit]]/Table1[[#This Row],[Sales]] -> -0.093785961 | Q182: United States | R182: East | S182: New Hampshire | T182: Goffstown | U182: 3045 | V182: 42108 | W182: =TEXT(Table1[[#This Row],[Order Date]],"mmmm") -> April | X182: =TEXT(Table1[[#This Row],[Order Date]],"yyyy") -> 2015 | Y182: 42110 | Z182: -22.82 | AA182: 8 | AB182: 243.32 | AC182: 89726 | AD182: =IF(COUNTIF(Returns!$A$2:$A$1635,Orders!AC182)>0,"Returned","Not Returned") -> Not Returned
A183: 18261 | B183: Critical | C183: 0.06 | D183: 276.2 | E183: 24.49 | F183: 335 | G183: =IF(COUNTIF(Table1[Customer ID],Table1[[#This Row],[Customer ID]])>1,"Repeat Customer","One-Time Customer") -> Repeat Customer | H183: Curtis O'Connell | I183: Regular Air | J183: Corporate | K183: Furniture | L183: Chairs & Chairmats | M183: Large Box | N183: SAFCO Arco Folding Chair | P183: =Table1[[#This Row],[Profit]]/Table1[[#This Row],[Sales]] -> 0.69 | Q183: United States | R183: West | S183: Oregon | T183: Medford | U183: 97504 | V183: 42128 | W183: =TEXT(Table1[[#This Row],[Order Date]],"mmmm") -> May | X183: =TEXT(Table1[[#This Row],[Order Date]],"yyyy") -> 2015 | Y183: 42129 | Z183: 2639.4708 | AA183: 14 | AB183: 3825.32 | AC183: 87277 | AD183: =IF(COUNTIF(Returns!$A$2:$A$1635,Orders!AC183)>0,"Returned","Not Returned") -> Not Returned
A184: 18262 | B184: Critical | C184: 0.09 | D184: 6.28 | E184: 5.29 | F184: 335 | G184: =IF(COUNTIF(Table1[Customer ID],Table1[[#This Row],[Customer ID]])>1,"Repeat Customer","One-Time Customer") -> Repeat Customer | H184: Curtis O'Connell | I184: Regular Air | J184: Corporate | K184: Furniture | L184: Office Furnishings | M184: Small Box | N184: Eldon® 200 Class™ Desk Accessories, Burgundy | O184: 0.43 | P184: =Table1[[#This Row],[Profit]]/Table1[[#This Row],[Sales]] -> -0.60961313 | Q184: United States | R184: West | S184: Oregon | T184: Medford | U184: 97504 | V184: 42128 | W184: =TEXT(Table1[[#This Row],[Order Date]],"mmmm") -> May | X184: =TEXT(Table1[[#This Row],[Order Date]],"yyyy") -> 2015 | Y184: 42128 | Z184: -5.2 | AA184: 1 | AB184: 8.53 | AC184: 87277 | AD184: =IF(COUNTIF(Returns!$A$2:$A$1635,Orders!AC184)>0,"Returned","Not Returned") -> Not Returned
A185: 23481 | B185: Medium | C185: 0.08 | D185: 7.77 | E185: 9.23 | F185: 339 | G185: =IF(COUNTIF(Table1[Customer ID],Table1[[#This Row],[Customer ID]])>1,"Repeat Customer","One-Time Customer") -> Repeat Customer | H185: Bobby Clements | I185: Regular Air | J185: Corporate | K185: Office Supplies | L185: Appliances | M185: Small Box | N185: Hoover Commercial Soft Guard Upright Vacuum And Disposable Filtration Bags | O185: 0.58 | P185: =Table1[[#This Row],[Profit]]/Table1[[#This Row],[Sales]] -> -2.0756824 | Q185: United States | R185: East | S185: Ohio | T185: Columbus | U185: 43229 | V185: 42080 | W185: =TEXT(Table1[[#This Row],[Order Date]],"mmmm") -> March | X185: =TEXT(Table1[[#This Row],[Order Date]],"yyyy") -> 2015 | Y185: 42081 | Z185: -83.65 | AA185: 5 | AB185: 40.3 | AC185: 90583 | AD185: =IF(COUNTIF(Returns!$A$2:$A$1635,Orders!AC185)>0,"Returned","Not Returned") -> Not Returned
A186: 23482 | B186: Medium | C186: 0.07 | D186: 7.59 | E186: 4 | F186: 339 | G186: =IF(COUNTIF(Table1[Customer ID],Table1[[#This Row],[Customer ID]])>1,"Repeat Customer","One-Time Customer") -> Repeat Customer | H186: Bobby Clements | I186: Regular Air | J186: Corporate | K186: Furniture | L186: Office Furnishings | M186: Wrap Bag | N186: Master Giant Foot® Doorstop, Safety Yellow | O186: 0.42 | P186: =Table1[[#This Row],[Profit]]/Table1[[#This Row],[Sales]] -> 0.21800143 | Q186: United States | R186: East | S186: Ohio | T186: Columbus | U186: 43229 | V186: 42080 | W186: =TEXT(Table1[[#This Row],[Order Date]],"mmmm") -> March | X186: =TEXT(Table1[[#This Row],[Order Date]],"yyyy") -> 2015 | Y186: 42082 | Z186: 24.39 | AA186: 15 | AB186: 111.88 | AC186: 90583 | AD186: =IF(COUNTIF(Returns!$A$2:$A$1635,Orders!AC186)>0,"Returned","Not Returned") -> Not Returned
A187: 480 | B187: Critical | C187: 0.01 | D187: 3.26 | E187: 1.86 | F187: 342 | G187: =IF(COUNTIF(Table1[Customer ID],Table1[[#This Row],[Customer ID]])>1,"Repeat Customer","One-Time Customer") -> One-Time Customer | H187: Jacqueline Noble | I187: Regular Air | J187: Corporate | K187: Office Supplies | L187: Pens & Art Supplies | M187: Wrap Bag | N187: Avery Hi-Liter GlideStik Fluorescent Highlighter, Yellow Ink | O187: 0.41 | P187: =Table1[[#This Row],[Profit]]/Table1[[#This Row],[Sales]] -> -0.063110721 | Q187: United States | R187: South | S187: Florida | T187: Miami | U187: 33181 | V187: 42128 | W187: =TEXT(Table1[[#This Row],[Order Date]],"mmmm") -> May | X187: =TEXT(Table1[[#This Row],[Order Date]],"yyyy") -> 2015 | Y187: 42130 | Z187: -4.6683 | AA187: 20 | AB187: 73.97 | AC187: 3332 | AD187: =IF(COUNTIF(Returns!$A$2:$A$1635,Orders!AC187)>0,"Returned","Not Returned") -> Not Returned
A188: 22784 | B188: Critical | C188: 0.03 | D188: 15.23 | E188: 27.75 | F188: 343 | G188: =IF(COUNTIF(Table1[Customer ID],Table1[[#This Row],[Customer ID]])>1,"Repeat Customer","One-Time Customer") -> One-Time Customer | H188: Lynn Epstein | I188: Delivery Truck | J188: Corporate | K188: Furniture | L188: Tables | M188: Jumbo Box | N188: Anderson Hickey Conga Table Tops & Accessories | O188: 0.76 | P188: =Table1[[#This Row],[Profit]]/Table1[[#This Row],[Sales]] -> 0.10415653 | Q188: United States | R188: East | S188: Maine | T188: Bangor | U188: 4401 | V188: 42035 | W188: =TEXT(Table1[[#This Row],[Order Date]],"mmmm") -> January | X188: =TEXT(Table1[[#This Row],[Order Date]],"yyyy") -> 2015 | Y188: 42036 | Z188: 11.65095 | AA188: 7 | AB188: 111.86 | AC188: 88151 | AD188: =IF(COUNTIF(Returns!$A$2:$A$1635,Orders!AC188)>0,"Returned","Not Returned") -> Not Returned
A189: 18480 | B189: Critical | C189: 0.01 | D189: 3.26 | E189: 1.86 | F189: 344 | G189: =IF(COUNTIF(Table1[Customer ID],Table1[[#This Row],[Customer ID]])>1,"Repeat Customer","One-Time Customer") -> One-Time Customer | H189: Rosemary English | I189: Regular Air | J189: Corporate | K189: Office Supplies | L189: Pens & Art Supplies | M189: Wrap Bag | N189: Avery Hi-Liter GlideStik Fluorescent Highlighter, Yellow Ink | O189: 0.41 | P189: =Table1[[#This Row],[Profit]]/Table1[[#This Row],[Sales]] -> 0.037966468 | Q189: United States | R189: East | S189: Maine | T189: Portland | U189: 4101 | V189: 42128 | W189: =TEXT(Table1[[#This Row],[Order Date]],"mmmm") -> May | X189: =TEXT(Table1[[#This Row],[Order Date]],"yyyy") -> 2015 | Y189: 42130 | Z189: 0.702 | AA189: 5 | AB189: 18.49 | AC189: 88152 | AD189: =IF(COUNTIF(Returns!$A$2:$A$1635,Orders!AC189)>0,"Returned","Not Returned") -> Not Returned
A190: 2408 | B190: Critical | C190: 0 | D190: 8.34 | E190: 2.64 | F190: 349 | G190: =IF(COUNTIF(Table1[Customer ID],Table1[[#This Row],[Customer ID]])>1,"Repeat Customer","One-Time Customer") -> Repeat Customer | H190: Kim Weiss | I190: Express Air | J190: Home Office | K190: Office Supplies | L190: Scissors, Rulers and Trimmers | M190: Small Pack | N190: Acme® Elite Stainless Steel Scissors | O190: 0.59 | P190: =Table1[[#This Row],[Profit]]/Table1[[#This Row],[Sales]] -> 0.027537696 | Q190: United States | R190: South | S190: Florida | T190: Miami | U190: 33132 | V190: 42164 | W190: =TEXT(Table1[[#This Row],[Order Date]],"mmmm") -> June | X190: =TEXT(Table1[[#This Row],[Order Date]],"yyyy") -> 2015 | Y190: 42166 | Z190: 5.8625 | AA190: 23 | AB190: 212.89 | AC190: 17446 | AD190: =IF(COUNTIF(Returns!$A$2:$A$1635,Orders!AC190)>0,"Returned","Not Returned") -> Not Returned
A191: 1595 | B191: Medium | C191: 0.04 | D191: 99.23 | E191: 8.99 | F191: 349 | G191: =IF(COUNTIF(Table1[Customer ID],Table1[[#This Row],[Customer ID]])>1,"Repeat Customer","One-Time Customer") -> Repeat Customer | H191: Kim Weiss | I191: Regular Air | J191: Home Office | K191: Furniture | L191: Office Furnishings | M191: Small Pack | N191: GE 48" Fluorescent Tube, Cool White Energy Saver, 34 Watts, 30/Box | O191: 0.35 | P191: =Table1[[#This Row],[Profit]]/Table1[[#This Row],[Sales]] -> 0.34499887 | Q191: United States | R191: South | S191: Florida | T191: Miami | U191: 33132 | V191: 42006 | W191: =TEXT(Table1[[#This Row],[Order Date]],"mmmm") -> January | X191: =TEXT(Table1[[#This Row],[Order Date]],"yyyy") -> 2015 | Y191: 42008 | Z191: 1916.6757 | AA191: 54 | AB191: 5555.6 | AC191: 11527 | AD191: =IF(COUNTIF(Returns!$A$2:$A$1635,Orders!AC191)>0,"Returned","Not Returned") -> Not Returned
A192: 20408 | B192: Critical | C192: 0 | D192: 8.34 | E192: 2.64 | F192: 351 | G192: =IF(COUNTIF(Table1[Customer ID],Table1[[#This Row],[Customer ID]])>1,"Repeat Customer","One-Time Customer") -> Repeat Customer | H192: Juanita Coley Knox | I192: Express Air | J192: Home Office | K192: Office Supplies | L192: Scissors, Rulers and Trimmers | M192: Small Pack | N192: Acme® Elite Stainless Steel Scissors | O192: 0.59 | P192: =Table1[[#This Row],[Profit]]/Table1[[#This Row],[Sales]] -> 0.18905293 | Q192: United States | R192: East | S192: New York | T192: Watertown | U192: 13601 | V192: 42164 | W192: =TEXT(Table1[[#This Row],[Order Date]],"mmmm") -> June | X192: =TEXT(Table1[[#This Row],[Order Date]],"yyyy") -> 2015 | Y192: 42166 | Z192: 10.5 | AA192: 6 | AB192: 55.54 | AC192: 88685 | AD192: =IF(COUNTIF(Returns!$A$2:$A$1635,Orders!AC192)>0,"Returned","Not Returned") -> Not Returned
A193: 19595 | B193: Medium | C193: 0.04 | D193: 99.23 | E193: 8.99 | F193: 351 | G193: =IF(COUNTIF(Table1[Customer ID],Table1[[#This Row],[Customer ID]])>1,"Repeat Customer","One-Time Customer") -> Repeat Customer | H193: Juanita Coley Knox | I193: Regular Air | J193: Home Office | K193: Furniture | L193: Office Furnishings | M193: Small Pack | N193: GE 48" Fluorescent Tube, Cool White Energy Saver, 34 Watts, 30/Box | O193: 0.35 | P193: =Table1[[#This Row],[Profit]]/Table1[[#This Row],[Sales]] -> 0.69 | Q193: United States | R193: East | S193: New York | T193: Watertown | U193: 13601 | V193: 42006 | W193: =TEXT(Table1[[#This Row],[Order Date]],"mmmm") -> January | X193: =TEXT(Table1[[#This Row],[Order Date]],"yyyy") -> 2015 | Y193: 42008 | Z193: 993.8346 | AA193: 14 | AB193: 1440.34 | AC193: 88686 | AD193: =IF(COUNTIF(Returns!$A$2:$A$1635,Orders!AC193)>0,"Returned","Not Returned") -> Not Returned
A194: 19107 | B194: Low | C194: 0.08 | D194: 4.89 | E194: 4.93 | F194: 353 | G194: =IF(COUNTIF(Table1[Customer ID],Table1[[#This Row],[Customer ID]])>1,"Repeat Customer","One-Time Customer") -> Repeat Customer | H194: Bonnie Chambers | I194: Express Air | J194: Home Office | K194: Technology | L194: Computer Peripherals | M194: Small Pack | N194: Maxell 3.5" DS/HD IBM-Formatted Diskettes, 10/Pack | O194: 0.66 | P194: =Table1[[#This Row],[Profit]]/Table1[[#This Row],[Sales]] -> -1.9519821 | Q194: United States | R194: West | S194: Arizona | T194: Glendale | U194: 85301 | V194: 42138 | W194: =TEXT(Table1[[#This Row],[Order Date]],"mmmm") -> May | X194: =TEXT(Table1[[#This Row],[Order Date]],"yyyy") -> 2015 | Y194: 42138 | Z194: -165.45 | AA194: 17 | AB194: 84.76 | AC194: 89647 | AD194: =IF(COUNTIF(Returns!$A$2:$A$1635,Orders!AC194)>0,"Returned","Not Returned") -> Not Returned
A195: 19108 | B195: Low | C195: 0.07 | D195: 6.68 | E195: 6.92 | F195: 353 | G195: =IF(COUNTIF(Table1[Customer ID],Table1[[#This Row],[Customer ID]])>1,"Repeat Customer","One-Time Customer") -> Repeat Customer | H195: Bonnie Chambers | I195: Regular Air | J195: Home Office | K195: Office Supplies | L195: Paper | M195: Small Box | N195: Xerox 1898 | O195: 0.37 | P195: =Table1[[#This Row],[Profit]]/Table1[[#This Row],[Sales]] -> -1.3460511 | Q195: United States | R195: West | S195: Arizona | T195: Glendale | U195: 85301 | V195: 42138 | W195: =TEXT(Table1[[#This Row],[Order Date]],"mmmm") -> May | X195: =TEXT(Table1[[#This Row],[Order Date]],"yyyy") -> 2015 | Y195: 42145 | Z195: -141.12 | AA195: 16 | AB195: 104.84 | AC195: 89647 | AD195: =IF(COUNTIF(Returns!$A$2:$A$1635,Orders!AC195)>0,"Returned","Not Returned") -> Not Returned
... A272: 21958 | B272: High | C272: 0.01 | D272: 20.98 | E272: 53.03 | F272: 508 | G272: =IF(COUNTIF(Table1[Customer ID],Table1[[#This Row],[Customer ID]])>1,"Repeat Customer","One-Time Customer") -> Repeat Customer | H272: Cameron Owens | I272: Delivery Truck | J272: Corporate | K272: Office Supplies | L272: Storage & Organization | M272: Jumbo Drum | N272: Tennsco Lockers, Gray | O272: 0.78 | P272: =Table1[[#This Row],[Profit]]/Table1[[#This Row],[Sales]] -> -2.293348 | Q272: United States | R272: South | S272: Kentucky | T272: Covington | U272: 41011 | V272: 42058 | W272: =TEXT(Table1[[#This Row],[Order Date]],"mmmm") -> February | X272: =TEXT(Table1[[#This Row],[Order Date]],"yyyy") -> 2015 | Y272: 42058 | Z272: -282.0818 | AA272: 5 | AB272: 123 | AC272: 87356 | AD272: =IF(COUNTIF(Returns!$A$2:$A$1635,Orders!AC272)>0,"Returned","Not Returned") -> Not Returned
A273: 18305 | B273: Critical | C273: 0.01 | D273: 128.24 | E273: 12.65 | F273: 508 | G273: =IF(COUNTIF(Table1[Customer ID],Table1[[#This Row],[Customer ID]])>1,"Repeat Customer","One-Time Customer") -> Repeat Customer | H273: Cameron Owens | I273: Regular Air | J273: Corporate | K273: Furniture | L273: Chairs & Chairmats | M273: Medium Box | N273: SAFCO Folding Chair Trolley | P273: =Table1[[#This Row],[Profit]]/Table1[[#This Row],[Sales]] -> 0.25291546 | Q273: United States | R273: South | S273: Kentucky | T273: Covington | U273: 41011 | V273: 42112 | W273: =TEXT(Table1[[#This Row],[Order Date]],"mmmm") -> April | X273: =TEXT(Table1[[#This Row],[Order Date]],"yyyy") -> 2015 | Y273: 42115 | Z273: 140.1354 | AA273: 4 | AB273: 554.08 | AC273: 87357 | AD273: =IF(COUNTIF(Returns!$A$2:$A$1635,Orders!AC273)>0,"Returned","Not Returned") -> Not Returned
A274: 19895 | B274: Low | C274: 0.02 | D274: 48.04 | E274: 5.09 | F274: 510 | G274: =IF(COUNTIF(Table1[Customer ID],Table1[[#This Row],[Customer ID]])>1,"Repeat Customer","One-Time Customer") -> Repeat Customer | H274: Gregory Rao | I274: Regular Air | J274: Corporate | K274: Office Supplies | L274: Paper | M274: Small Box | N274: Xerox 1910 | O274: 0.37 | P274: =Table1[[#This Row],[Profit]]/Table1[[#This Row],[Sales]] -> 0.69 | Q274: United States | R274: West | S274: California | T274: Manteca | U274: 95336 | V274: 42017 | W274: =TEXT(Table1[[#This Row],[Order Date]],"mmmm") -> January | X274: =TEXT(Table1[[#This Row],[Order Date]],"yyyy") -> 2015 | Y274: 42017 | Z274: 105.2526 | AA274: 3 | AB274: 152.54 | AC274: 90058 | AD274: =IF(COUNTIF(Returns!$A$2:$A$1635,Orders!AC274)>0,"Returned","Not Returned") -> Not Returned
A275: 20007 | B275: Critical | C275: 0.03 | D275: 6.37 | E275: 5.19 | F275: 510 | G275: =IF(COUNTIF(Table1[Customer ID],Table1[[#This Row],[Customer ID]])>1,"Repeat Customer","One-Time Customer") -> Repeat Customer | H275: Gregory Rao | I275: Regular Air | J275: Corporate | K275: Office Supplies | L275: Binders and Binder Accessories | M275: Small Box | N275: C-Line Peel & Stick Add-On Filing Pockets, 8-3/4 x 5-1/8, 10/Pack | O275: 0.38 | P275: =Table1[[#This Row],[Profit]]/Table1[[#This Row],[Sales]] -> -0.32400824 | Q275: United States | R275: West | S275: California | T275: Manteca | U275: 95336 | V275: 42036 | W275: =TEXT(Table1[[#This Row],[Order Date]],"mmmm") -> February | X275: =TEXT(Table1[[#This Row],[Order Date]],"yyyy") -> 2015 | Y275: 42037 | Z275: -29.0927 | AA275: 14 | AB275: 89.79 | AC275: 90059 | AD275: =IF(COUNTIF(Returns!$A$2:$A$1635,Orders!AC275)>0,"Returned","Not Returned") -> Not Returned
A276: 20216 | B276: Low | C276: 0.07 | D276: 12.64 | E276: 4.98 | F276: 518 | G276: =IF(COUNTIF(Table1[Customer ID],Table1[[#This Row],[Customer ID]])>1,"Repeat Customer","One-Time Customer") -> One-Time Customer | H276: Mark Ritchie | I276: Regular Air | J276: Home Office | K276: Furniture | L276: Office Furnishings | M276: Small Pack | N276: Nu-Dell Executive Frame | O276: 0.48 | P276: =Table1[[#This Row],[Profit]]/Table1[[#This Row],[Sales]] -> 0.56775631 | Q276: United States | R276: Central | S276: Missouri | T276: Clayton | U276: 63105 | V276: 42160 | W276: =TEXT(Table1[[#This Row],[Order Date]],"mmmm") -> June | X276: =TEXT(Table1[[#This Row],[Order Date]],"yyyy") -> 2015 | Y276: 42167 | Z276: 113.415 | AA276: 16 | AB276: 199.76 | AC276: 90867 | AD276: =IF(COUNTIF(Returns!$A$2:$A$1635,Orders!AC276)>0,"Returned","Not Returned") -> Not Returned
A277: 23200 | B277: Medium | C277: 0.02 | D277: 150.98 | E277: 13.99 | F277: 522 | G277: =IF(COUNTIF(Table1[Customer ID],Table1[[#This Row],[Customer ID]])>1,"Repeat Customer","One-Time Customer") -> Repeat Customer | H277: Aaron Riggs | I277: Express Air | J277: Small Business | K277: Technology | L277: Office Machines | M277: Medium Box | N277: Canon MP41DH Printing Calculator | O277: 0.38 | P277: =Table1[[#This Row],[Profit]]/Table1[[#This Row],[Sales]] -> 0.054333118 | Q277: United States | R277: West | S277: Oregon | T277: Redmond | U277: 97756 | V277: 42177 | W277: =TEXT(Table1[[#This Row],[Order Date]],"mmmm") -> June | X277: =TEXT(Table1[[#This Row],[Order Date]],"yyyy") -> 2015 | Y277: 42179 | Z277: 26.1 | AA277: 3 | AB277: 480.37 | AC277: 89327 | AD277: =IF(COUNTIF(Returns!$A$2:$A$1635,Orders!AC277)>0,"Returned","Not Returned") -> Not Returned
A278: 23201 | B278: Medium | C278: 0.1 | D278: 5.43 | E278: 0.95 | F278: 522 | G278: =IF(COUNTIF(Table1[Customer ID],Table1[[#This Row],[Customer ID]])>1,"Repeat Customer","One-Time Customer") -> Repeat Customer | H278: Aaron Riggs | I278: Regular Air | J278: Small Business | K278: Office Supplies | L278: Paper | M278: Wrap Bag | N278: Wirebound Message Book, 4 per Page | O278: 0.36 | P278: =Table1[[#This Row],[Profit]]/Table1[[#This Row],[Sales]] -> -0.44791667 | Q278: United States | R278: West | S278: Oregon | T278: Redmond | U278: 97756 | V278: 42177 | W278: =TEXT(Table1[[#This Row],[Order Date]],"mmmm") -> June | X278: =TEXT(Table1[[#This Row],[Order Date]],"yyyy") -> 2015 | Y278: 42179 | Z278: -2.58 | AA278: 1 | AB278: 5.76 | AC278: 89327 | AD278: =IF(COUNTIF(Returns!$A$2:$A$1635,Orders!AC278)>0,"Returned","Not Returned") -> Not Returned
A279: 23202 | B279: Medium | C279: 0.01 | D279: 179.29 | E279: 29.21 | F279: 522 | G279: =IF(COUNTIF(Table1[Customer ID],Table1[[#This Row],[Customer ID]])>1,"Repeat Customer","One-Time Customer") -> Repeat Customer | H279: Aaron Riggs | I279: Delivery Truck | J279: Small Business | K279: Furniture | L279: Tables | M279: Jumbo Box | N279: Bevis Round Conference Table Top, X-Base | O279: 0.74 | P279: =Table1[[#This Row],[Profit]]/Table1[[#This Row],[Sales]] -> 0.89974391 | Q279: United States | R279: West | S279: Oregon | T279: Redmond | U279: 97756 | V279: 42177 | W279: =TEXT(Table1[[#This Row],[Order Date]],"mmmm") -> June | X279: =TEXT(Table1[[#This Row],[Order Date]],"yyyy") -> 2015 | Y279: 42178 | Z279: 2800.12 | AA279: 21 | AB279: 3112.13 | AC279: 89327 | AD279: =IF(COUNTIF(Returns!$A$2:$A$1635,Orders!AC279)>0,"Returned","Not Returned") -> Not Returned
A280: 21517 | B280: Not Specified | C280: 0.03 | D280: 1270.99 | E280: 19.99 | F280: 524 | G280: =IF(COUNTIF(Table1[Customer ID],Table1[[#This Row],[Customer ID]])>1,"Repeat Customer","One-Time Customer") -> Repeat Customer | H280: Gina McKnight | I280: Regular Air | J280: Consumer | K280: Office Supplies | L280: Binders and Binder Accessories | M280: Small Box | N280: Fellowes PB500 Electric Punch Plastic Comb Binding Machine with Manual Bind | O280: 0.35 | P280: =Table1[[#This Row],[Profit]]/Table1[[#This Row],[Sales]] -> 0.14042124 | Q280: United States | R280: South | S280: Tennessee | T280: Farragut | U280: 37922 | V280: 42024 | W280: =TEXT(Table1[[#This Row],[Order Date]],"mmmm") -> January | X280: =TEXT(Table1[[#This Row],[Order Date]],"yyyy") -> 2015 | Y280: 42026 | Z280: 363.552 | AA280: 2 | AB280: 2589.01 | AC280: 91127 | AD280: =IF(COUNTIF(Returns!$A$2:$A$1635,Orders!AC280)>0,"Returned","Not Returned") -> Not Returned
A281: 21518 | B281: Not Specified | C281: 0.07 | D281: 2036.48 | E281: 14.7 | F281: 524 | G281: =IF(COUNTIF(Table1[Customer ID],Table1[[#This Row],[Customer ID]])>1,"Repeat Customer","One-Time Customer") -> Repeat Customer | H281: Gina McKnight | I281: Delivery Truck | J281: Consumer | K281: Technology | L281: Office Machines | M281: Jumbo Drum | N281: Lexmark 4227 Plus Dot Matrix Printer | O281: 0.55 | P281: =Table1[[#This Row],[Profit]]/Table1[[#This Row],[Sales]] -> -0.0060910382 | Q281: United States | R281: South | S281: Tennessee | T281: Farragut | U281: 37922 | V281: 42024 | W281: =TEXT(Table1[[#This Row],[Order Date]],"mmmm") -> January | X281: =TEXT(Table1[[#This Row],[Order Date]],"yyyy") -> 2015 | Y281: 42026 | Z281: -11.536 | AA281: 1 | AB281: 1893.93 | AC281: 91127 | AD281: =IF(COUNTIF(Returns!$A$2:$A$1635,Orders!AC281)>0,"Returned","Not Returned") -> Not Returned
A282: 22176 | B282: High | C282: 0.09 | D282: 17.98 | E282: 8.51 | F282: 526 | G282: =IF(COUNTIF(Table1[Customer ID],Table1[[#This Row],[Customer ID]])>1,"Repeat Customer","One-Time Customer") -> Repeat Customer | H282: April Hu | I282: Regular Air | J282: Home Office | K282: Technology | L282: Office Machines | M282: Medium Box | N282: Canon P1-DHIII Palm Printing Calculator | O282: 0.4 | P282: =Table1[[#This Row],[Profit]]/Table1[[#This Row],[Sales]] -> -0.031317198 | Q282: United States | R282: West | S282: Arizona | T282: Mesa | U282: 85204 | V282: 42149 | W282: =TEXT(Table1[[#This Row],[Order Date]],"mmmm") -> May | X282: =TEXT(Table1[[#This Row],[Order Date]],"yyyy") -> 2015 | Y282: 42151 | Z282: -6.612 | AA282: 12 | AB282: 211.13 | AC282: 90026 | AD282: =IF(COUNTIF(Returns!$A$2:$A$1635,Orders!AC282)>0,"Returned","Not Returned") -> Not Returned
A283: 20494 | B283: Not Specified | C283: 0 | D283: 1.88 | E283: 1.49 | F283: 526 | G283: =IF(COUNTIF(Table1[Customer ID],Table1[[#This Row],[Customer ID]])>1,"Repeat Customer","One-Time Customer") -> Repeat Customer | H283: April Hu | I283: Regular Air | J283: Home Office | K283: Office Supplies | L283: Binders and Binder Accessories | M283: Small Box | N283: Staples® General Use 3-Ring Binders | O283: 0.37 | P283: =Table1[[#This Row],[Profit]]/Table1[[#This Row],[Sales]] -> -0.61282001 | Q283: United States | R283: West | S283: Arizona | T283: Mesa | U283: 85204 | V283: 42021 | W283: =TEXT(Table1[[#This Row],[Order Date]],"mmmm") -> January | X283: =TEXT(Table1[[#This Row],[Order Date]],"yyyy") -> 2015 | Y283: 42022 | Z283: -15.5595 | AA283: 13 | AB283: 25.39 | AC283: 90027 | AD283: =IF(COUNTIF(Returns!$A$2:$A$1635,Orders!AC283)>0,"Returned","Not Returned") -> Not Returned
A284: 20495 | B284: Not Specified | C284: 0.06 | D284: 5.78 | E284: 5.67 | F284: 526 | G284: =IF(COUNTIF(Table1[Customer ID],Table1[[#This Row],[Customer ID]])>1,"Repeat Customer","One-Time Customer") -> Repeat Customer | H284: April Hu | I284: Regular Air | J284: Home Office | K284: Office Supplies | L284: Paper | M284: Small Box | N284: Xerox 1978 | O284: 0.36 | P284: =Table1[[#This Row],[Profit]]/Table1[[#This Row],[Sales]] -> -1.2397158 | Q284: United States | R284: West | S284: Arizona | T284: Mesa | U284: 85204 | V284: 42021 | W284: =TEXT(Table1[[#This Row],[Order Date]],"mmmm") -> January | X284: =TEXT(Table1[[#This Row],[Order Date]],"yyyy") -> 2015 | Y284: 42022 | Z284: -108.19 | AA284: 15 | AB284: 87.27 | AC284: 90027 | AD284: =IF(COUNTIF(Returns!$A$2:$A$1635,Orders!AC284)>0,"Returned","Not Returned") -> Not Returned
...

Sheet Returns
A1: Order ID | B1: Status
A2: 65 | B2: Returned
A3: 612 | B3: Returned
A4: 614 | B4: Returned
A5: 678 | B5: Returned
A6: 710 | B6: Returned
A7: 740 | B7: Returned
A8: 775 | B8: Returned
A9: 833 | B9: Returned
A10: 902 | B10: Returned
A11: 3300 | B11: Returned
A12: 3456 | B12: Returned
A13: 3525 | B13: Returned
... A1635: 182906 | B1635: Returned
